{
 "cells": [
  {
   "cell_type": "markdown",
   "metadata": {},
   "source": [
    "# Deep Neural Network for MNIST Classification\n",
    "\n",
    "We'll apply all the knowledge from the lectures in this section to write a deep neural network. The problem we've chosen is referred to as the \"Hello World\" of deep learning because for most students it is the first deep learning algorithm they see.\n",
    "\n",
    "The dataset is called MNIST and refers to handwritten digit recognition. You can find more about it on Yann LeCun's website (Director of AI Research, Facebook). He is one of the pioneers of what we've been talking about and of more complex approaches that are widely used today, such as covolutional neural networks (CNNs). \n",
    "\n",
    "The dataset provides 70,000 images (28x28 pixels) of handwritten digits (1 digit per image). \n",
    "\n",
    "The goal is to write an algorithm that detects which digit is written. Since there are only 10 digits (0, 1, 2, 3, 4, 5, 6, 7, 8, 9), this is a classification problem with 10 classes. \n",
    "\n",
    "Our goal would be to build a neural network with 2 hidden layers."
   ]
  },
  {
   "cell_type": "markdown",
   "metadata": {},
   "source": [
    "## Import the relevant packages"
   ]
  },
  {
   "cell_type": "code",
   "execution_count": 1,
   "metadata": {},
   "outputs": [],
   "source": [
    "import numpy as np\n",
    "import tensorflow as tf\n",
    "\n",
    "# TensorFLow includes a data provider for MNIST that we'll use.\n",
    "# It comes with the tensorflow-datasets module, therefore, if you haven't please install the package using\n",
    "# pip install tensorflow-datasets \n",
    "# or\n",
    "# conda install tensorflow-datasets\n",
    "\n",
    "import tensorflow_datasets as tfds\n",
    "\n",
    "# these datasets will be stored in C:\\Users\\*USERNAME*\\tensorflow_datasets\\...\n",
    "# the first time you download a dataset, it is stored in the respective folder \n",
    "# every other time, it is automatically loading the copy on your computer "
   ]
  },
  {
   "cell_type": "markdown",
   "metadata": {},
   "source": [
    "## Data\n",
    "\n",
    "That's where we load and preprocess our data."
   ]
  },
  {
   "cell_type": "code",
   "execution_count": 2,
   "metadata": {},
   "outputs": [
    {
     "name": "stdout",
     "output_type": "stream",
     "text": [
      "WARNING:tensorflow:AutoGraph could not transform <bound method TopLevelFeature.decode_example of FeaturesDict({\n",
      "    'image': Image(shape=(28, 28, 1), dtype=tf.uint8),\n",
      "    'label': ClassLabel(shape=(), dtype=tf.int64, num_classes=10),\n",
      "})> and will run it as-is.\n",
      "Please report this to the TensorFlow team. When filing the bug, set the verbosity to 10 (on Linux, `export AUTOGRAPH_VERBOSITY=10`) and attach the full output.\n",
      "Cause: No module named 'tensorflow_core.estimator'\n"
     ]
    },
    {
     "name": "stderr",
     "output_type": "stream",
     "text": [
      "WARNING:tensorflow:AutoGraph could not transform <bound method TopLevelFeature.decode_example of FeaturesDict({\n",
      "    'image': Image(shape=(28, 28, 1), dtype=tf.uint8),\n",
      "    'label': ClassLabel(shape=(), dtype=tf.int64, num_classes=10),\n",
      "})> and will run it as-is.\n",
      "Please report this to the TensorFlow team. When filing the bug, set the verbosity to 10 (on Linux, `export AUTOGRAPH_VERBOSITY=10`) and attach the full output.\n",
      "Cause: No module named 'tensorflow_core.estimator'\n",
      "WARNING:absl:Warning: Setting shuffle_files=True because split=TRAIN and shuffle_files=None. This behavior will be deprecated on 2019-08-06, at which point shuffle_files=False will be the default for all splits.\n"
     ]
    },
    {
     "name": "stdout",
     "output_type": "stream",
     "text": [
      "WARNING: AutoGraph could not transform <bound method TopLevelFeature.decode_example of FeaturesDict({\n",
      "    'image': Image(shape=(28, 28, 1), dtype=tf.uint8),\n",
      "    'label': ClassLabel(shape=(), dtype=tf.int64, num_classes=10),\n",
      "})> and will run it as-is.\n",
      "Please report this to the TensorFlow team. When filing the bug, set the verbosity to 10 (on Linux, `export AUTOGRAPH_VERBOSITY=10`) and attach the full output.\n",
      "Cause: No module named 'tensorflow_core.estimator'\n",
      "WARNING:tensorflow:AutoGraph could not transform <bound method TopLevelFeature.decode_example of FeaturesDict({\n",
      "    'image': Image(shape=(28, 28, 1), dtype=tf.uint8),\n",
      "    'label': ClassLabel(shape=(), dtype=tf.int64, num_classes=10),\n",
      "})> and will run it as-is.\n",
      "Please report this to the TensorFlow team. When filing the bug, set the verbosity to 10 (on Linux, `export AUTOGRAPH_VERBOSITY=10`) and attach the full output.\n",
      "Cause: No module named 'tensorflow_core.estimator'\n"
     ]
    },
    {
     "name": "stderr",
     "output_type": "stream",
     "text": [
      "WARNING:tensorflow:AutoGraph could not transform <bound method TopLevelFeature.decode_example of FeaturesDict({\n",
      "    'image': Image(shape=(28, 28, 1), dtype=tf.uint8),\n",
      "    'label': ClassLabel(shape=(), dtype=tf.int64, num_classes=10),\n",
      "})> and will run it as-is.\n",
      "Please report this to the TensorFlow team. When filing the bug, set the verbosity to 10 (on Linux, `export AUTOGRAPH_VERBOSITY=10`) and attach the full output.\n",
      "Cause: No module named 'tensorflow_core.estimator'\n"
     ]
    },
    {
     "name": "stdout",
     "output_type": "stream",
     "text": [
      "WARNING: AutoGraph could not transform <bound method TopLevelFeature.decode_example of FeaturesDict({\n",
      "    'image': Image(shape=(28, 28, 1), dtype=tf.uint8),\n",
      "    'label': ClassLabel(shape=(), dtype=tf.int64, num_classes=10),\n",
      "})> and will run it as-is.\n",
      "Please report this to the TensorFlow team. When filing the bug, set the verbosity to 10 (on Linux, `export AUTOGRAPH_VERBOSITY=10`) and attach the full output.\n",
      "Cause: No module named 'tensorflow_core.estimator'\n"
     ]
    }
   ],
   "source": [
    "# remember the comment from above\n",
    "# these datasets will be stored in C:\\Users\\*USERNAME*\\tensorflow_datasets\\...\n",
    "# the first time you download a dataset, it is stored in the respective folder \n",
    "# every other time, it is automatically loading the copy on your computer \n",
    "\n",
    "# tfds.load actually loads a dataset (or downloads and then loads if that's the first time you use it) \n",
    "# in our case, we are interesteed in the MNIST; the name of the dataset is the only mandatory argument\n",
    "# there are other arguments we can specify, which we can find useful\n",
    "# mnist_dataset = tfds.load(name='mnist', as_supervised=True)\n",
    "mnist_dataset, mnist_info = tfds.load(name='mnist', with_info=True, as_supervised=True)\n",
    "# with_info=True will also provide us with a tuple containing information about the version, features, number of samples\n",
    "# we will use this information a bit below and we will store it in mnist_info\n",
    "\n",
    "# as_supervised=True will load the dataset in a 2-tuple structure (input, target) \n",
    "# alternatively, as_supervised=False, would return a dictionary\n",
    "# obviously we prefer to have our inputs and targets separated "
   ]
  },
  {
   "cell_type": "code",
   "execution_count": null,
   "metadata": {},
   "outputs": [
    {
     "name": "stderr",
     "output_type": "stream",
     "text": [
      "ERROR:root:Internal Python error in the inspect module.\n",
      "Below is the traceback from this internal error.\n",
      "\n",
      "ERROR:root:Internal Python error in the inspect module.\n",
      "Below is the traceback from this internal error.\n",
      "\n",
      "ERROR:root:Internal Python error in the inspect module.\n",
      "Below is the traceback from this internal error.\n",
      "\n"
     ]
    },
    {
     "name": "stdout",
     "output_type": "stream",
     "text": [
      "Traceback (most recent call last):\n",
      "  File \"C:\\Users\\LENOVO\\Anaconda\\envs\\py36\\lib\\site-packages\\IPython\\core\\interactiveshell.py\", line 3343, in run_code\n",
      "    exec(code_obj, self.user_global_ns, self.user_ns)\n",
      "  File \"<ipython-input-4-0a36ac32e0b5>\", line 1, in <module>\n",
      "    mnist_train,mnist_test = mnist_dataset['train'].mnist_dataset['test']\n",
      "AttributeError: '_OptionsDataset' object has no attribute 'mnist_dataset'\n",
      "\n",
      "During handling of the above exception, another exception occurred:\n",
      "\n",
      "Traceback (most recent call last):\n",
      "  File \"C:\\Users\\LENOVO\\Anaconda\\envs\\py36\\lib\\site-packages\\IPython\\core\\interactiveshell.py\", line 2044, in showtraceback\n",
      "    stb = value._render_traceback_()\n",
      "AttributeError: 'AttributeError' object has no attribute '_render_traceback_'\n",
      "\n",
      "During handling of the above exception, another exception occurred:\n",
      "\n",
      "Traceback (most recent call last):\n",
      "  File \"C:\\Users\\LENOVO\\Anaconda\\envs\\py36\\lib\\site-packages\\IPython\\core\\ultratb.py\", line 1169, in get_records\n",
      "    return _fixed_getinnerframes(etb, number_of_lines_of_context, tb_offset)\n",
      "  File \"C:\\Users\\LENOVO\\Anaconda\\envs\\py36\\lib\\site-packages\\IPython\\core\\ultratb.py\", line 316, in wrapped\n",
      "    return f(*args, **kwargs)\n",
      "  File \"C:\\Users\\LENOVO\\Anaconda\\envs\\py36\\lib\\site-packages\\IPython\\core\\ultratb.py\", line 350, in _fixed_getinnerframes\n",
      "    records = fix_frame_records_filenames(inspect.getinnerframes(etb, context))\n",
      "  File \"C:\\Users\\LENOVO\\Anaconda\\envs\\py36\\lib\\inspect.py\", line 1490, in getinnerframes\n",
      "    frameinfo = (tb.tb_frame,) + getframeinfo(tb, context)\n",
      "  File \"C:\\Users\\LENOVO\\Anaconda\\envs\\py36\\lib\\inspect.py\", line 1448, in getframeinfo\n",
      "    filename = getsourcefile(frame) or getfile(frame)\n",
      "  File \"C:\\Users\\LENOVO\\Anaconda\\envs\\py36\\lib\\inspect.py\", line 696, in getsourcefile\n",
      "    if getattr(getmodule(object, filename), '__loader__', None) is not None:\n",
      "  File \"C:\\Users\\LENOVO\\Anaconda\\envs\\py36\\lib\\inspect.py\", line 733, in getmodule\n",
      "    if ismodule(module) and hasattr(module, '__file__'):\n",
      "  File \"C:\\Users\\LENOVO\\Anaconda\\envs\\py36\\lib\\site-packages\\tensorflow\\__init__.py\", line 50, in __getattr__\n",
      "    module = self._load()\n",
      "  File \"C:\\Users\\LENOVO\\Anaconda\\envs\\py36\\lib\\site-packages\\tensorflow\\__init__.py\", line 44, in _load\n",
      "    module = _importlib.import_module(self.__name__)\n",
      "  File \"C:\\Users\\LENOVO\\Anaconda\\envs\\py36\\lib\\importlib\\__init__.py\", line 126, in import_module\n",
      "    return _bootstrap._gcd_import(name[level:], package, level)\n",
      "  File \"<frozen importlib._bootstrap>\", line 994, in _gcd_import\n",
      "  File \"<frozen importlib._bootstrap>\", line 971, in _find_and_load\n",
      "  File \"<frozen importlib._bootstrap>\", line 953, in _find_and_load_unlocked\n",
      "ModuleNotFoundError: No module named 'tensorflow_core.estimator'\n",
      "Traceback (most recent call last):\n",
      "  File \"C:\\Users\\LENOVO\\Anaconda\\envs\\py36\\lib\\site-packages\\IPython\\core\\interactiveshell.py\", line 3343, in run_code\n",
      "    exec(code_obj, self.user_global_ns, self.user_ns)\n",
      "  File \"<ipython-input-4-0a36ac32e0b5>\", line 1, in <module>\n",
      "    mnist_train,mnist_test = mnist_dataset['train'].mnist_dataset['test']\n",
      "AttributeError: '_OptionsDataset' object has no attribute 'mnist_dataset'\n",
      "\n",
      "During handling of the above exception, another exception occurred:\n",
      "\n",
      "Traceback (most recent call last):\n",
      "  File \"C:\\Users\\LENOVO\\Anaconda\\envs\\py36\\lib\\site-packages\\IPython\\core\\interactiveshell.py\", line 2044, in showtraceback\n",
      "    stb = value._render_traceback_()\n",
      "AttributeError: 'AttributeError' object has no attribute '_render_traceback_'\n",
      "\n",
      "During handling of the above exception, another exception occurred:\n",
      "\n",
      "Traceback (most recent call last):\n",
      "  File \"C:\\Users\\LENOVO\\Anaconda\\envs\\py36\\lib\\site-packages\\IPython\\core\\interactiveshell.py\", line 3263, in run_ast_nodes\n",
      "    if (await self.run_code(code, result,  async_=asy)):\n",
      "  File \"C:\\Users\\LENOVO\\Anaconda\\envs\\py36\\lib\\site-packages\\IPython\\core\\interactiveshell.py\", line 3360, in run_code\n",
      "    self.showtraceback(running_compiled_code=True)\n",
      "  File \"C:\\Users\\LENOVO\\Anaconda\\envs\\py36\\lib\\site-packages\\IPython\\core\\interactiveshell.py\", line 2047, in showtraceback\n",
      "    value, tb, tb_offset=tb_offset)\n",
      "  File \"C:\\Users\\LENOVO\\Anaconda\\envs\\py36\\lib\\site-packages\\IPython\\core\\ultratb.py\", line 1436, in structured_traceback\n",
      "    self, etype, value, tb, tb_offset, number_of_lines_of_context)\n",
      "  File \"C:\\Users\\LENOVO\\Anaconda\\envs\\py36\\lib\\site-packages\\IPython\\core\\ultratb.py\", line 1336, in structured_traceback\n",
      "    self, etype, value, tb, tb_offset, number_of_lines_of_context\n",
      "  File \"C:\\Users\\LENOVO\\Anaconda\\envs\\py36\\lib\\site-packages\\IPython\\core\\ultratb.py\", line 1193, in structured_traceback\n",
      "    tb_offset)\n",
      "  File \"C:\\Users\\LENOVO\\Anaconda\\envs\\py36\\lib\\site-packages\\IPython\\core\\ultratb.py\", line 1150, in format_exception_as_a_whole\n",
      "    last_unique, recursion_repeat = find_recursion(orig_etype, evalue, records)\n",
      "  File \"C:\\Users\\LENOVO\\Anaconda\\envs\\py36\\lib\\site-packages\\IPython\\core\\ultratb.py\", line 451, in find_recursion\n",
      "    return len(records), 0\n",
      "TypeError: object of type 'NoneType' has no len()\n",
      "\n",
      "During handling of the above exception, another exception occurred:\n",
      "\n",
      "Traceback (most recent call last):\n",
      "  File \"C:\\Users\\LENOVO\\Anaconda\\envs\\py36\\lib\\site-packages\\IPython\\core\\interactiveshell.py\", line 2044, in showtraceback\n",
      "    stb = value._render_traceback_()\n",
      "AttributeError: 'TypeError' object has no attribute '_render_traceback_'\n",
      "\n",
      "During handling of the above exception, another exception occurred:\n",
      "\n",
      "Traceback (most recent call last):\n",
      "  File \"C:\\Users\\LENOVO\\Anaconda\\envs\\py36\\lib\\site-packages\\IPython\\core\\ultratb.py\", line 1169, in get_records\n",
      "    return _fixed_getinnerframes(etb, number_of_lines_of_context, tb_offset)\n",
      "  File \"C:\\Users\\LENOVO\\Anaconda\\envs\\py36\\lib\\site-packages\\IPython\\core\\ultratb.py\", line 316, in wrapped\n",
      "    return f(*args, **kwargs)\n",
      "  File \"C:\\Users\\LENOVO\\Anaconda\\envs\\py36\\lib\\site-packages\\IPython\\core\\ultratb.py\", line 350, in _fixed_getinnerframes\n",
      "    records = fix_frame_records_filenames(inspect.getinnerframes(etb, context))\n",
      "  File \"C:\\Users\\LENOVO\\Anaconda\\envs\\py36\\lib\\inspect.py\", line 1490, in getinnerframes\n",
      "    frameinfo = (tb.tb_frame,) + getframeinfo(tb, context)\n",
      "  File \"C:\\Users\\LENOVO\\Anaconda\\envs\\py36\\lib\\inspect.py\", line 1448, in getframeinfo\n",
      "    filename = getsourcefile(frame) or getfile(frame)\n",
      "  File \"C:\\Users\\LENOVO\\Anaconda\\envs\\py36\\lib\\inspect.py\", line 696, in getsourcefile\n",
      "    if getattr(getmodule(object, filename), '__loader__', None) is not None:\n",
      "  File \"C:\\Users\\LENOVO\\Anaconda\\envs\\py36\\lib\\inspect.py\", line 733, in getmodule\n",
      "    if ismodule(module) and hasattr(module, '__file__'):\n",
      "  File \"C:\\Users\\LENOVO\\Anaconda\\envs\\py36\\lib\\site-packages\\tensorflow\\__init__.py\", line 50, in __getattr__\n",
      "    module = self._load()\n",
      "  File \"C:\\Users\\LENOVO\\Anaconda\\envs\\py36\\lib\\site-packages\\tensorflow\\__init__.py\", line 44, in _load\n",
      "    module = _importlib.import_module(self.__name__)\n",
      "  File \"C:\\Users\\LENOVO\\Anaconda\\envs\\py36\\lib\\importlib\\__init__.py\", line 126, in import_module\n",
      "    return _bootstrap._gcd_import(name[level:], package, level)\n",
      "  File \"<frozen importlib._bootstrap>\", line 994, in _gcd_import\n",
      "  File \"<frozen importlib._bootstrap>\", line 971, in _find_and_load\n",
      "  File \"<frozen importlib._bootstrap>\", line 953, in _find_and_load_unlocked\n",
      "ModuleNotFoundError: No module named 'tensorflow_core.estimator'\n",
      "Traceback (most recent call last):\n",
      "  File \"C:\\Users\\LENOVO\\Anaconda\\envs\\py36\\lib\\site-packages\\IPython\\core\\interactiveshell.py\", line 3343, in run_code\n",
      "    exec(code_obj, self.user_global_ns, self.user_ns)\n",
      "  File \"<ipython-input-4-0a36ac32e0b5>\", line 1, in <module>\n",
      "    mnist_train,mnist_test = mnist_dataset['train'].mnist_dataset['test']\n",
      "AttributeError: '_OptionsDataset' object has no attribute 'mnist_dataset'\n",
      "\n",
      "During handling of the above exception, another exception occurred:\n",
      "\n",
      "Traceback (most recent call last):\n",
      "  File \"C:\\Users\\LENOVO\\Anaconda\\envs\\py36\\lib\\site-packages\\IPython\\core\\interactiveshell.py\", line 2044, in showtraceback\n",
      "    stb = value._render_traceback_()\n",
      "AttributeError: 'AttributeError' object has no attribute '_render_traceback_'\n",
      "\n",
      "During handling of the above exception, another exception occurred:\n",
      "\n",
      "Traceback (most recent call last):\n",
      "  File \"C:\\Users\\LENOVO\\Anaconda\\envs\\py36\\lib\\site-packages\\IPython\\core\\interactiveshell.py\", line 3263, in run_ast_nodes\n",
      "    if (await self.run_code(code, result,  async_=asy)):\n",
      "  File \"C:\\Users\\LENOVO\\Anaconda\\envs\\py36\\lib\\site-packages\\IPython\\core\\interactiveshell.py\", line 3360, in run_code\n",
      "    self.showtraceback(running_compiled_code=True)\n",
      "  File \"C:\\Users\\LENOVO\\Anaconda\\envs\\py36\\lib\\site-packages\\IPython\\core\\interactiveshell.py\", line 2047, in showtraceback\n",
      "    value, tb, tb_offset=tb_offset)\n",
      "  File \"C:\\Users\\LENOVO\\Anaconda\\envs\\py36\\lib\\site-packages\\IPython\\core\\ultratb.py\", line 1436, in structured_traceback\n",
      "    self, etype, value, tb, tb_offset, number_of_lines_of_context)\n",
      "  File \"C:\\Users\\LENOVO\\Anaconda\\envs\\py36\\lib\\site-packages\\IPython\\core\\ultratb.py\", line 1336, in structured_traceback\n",
      "    self, etype, value, tb, tb_offset, number_of_lines_of_context\n",
      "  File \"C:\\Users\\LENOVO\\Anaconda\\envs\\py36\\lib\\site-packages\\IPython\\core\\ultratb.py\", line 1193, in structured_traceback\n",
      "    tb_offset)\n",
      "  File \"C:\\Users\\LENOVO\\Anaconda\\envs\\py36\\lib\\site-packages\\IPython\\core\\ultratb.py\", line 1150, in format_exception_as_a_whole\n",
      "    last_unique, recursion_repeat = find_recursion(orig_etype, evalue, records)\n",
      "  File \"C:\\Users\\LENOVO\\Anaconda\\envs\\py36\\lib\\site-packages\\IPython\\core\\ultratb.py\", line 451, in find_recursion\n",
      "    return len(records), 0\n",
      "TypeError: object of type 'NoneType' has no len()\n",
      "\n",
      "During handling of the above exception, another exception occurred:\n",
      "\n",
      "Traceback (most recent call last):\n",
      "  File \"C:\\Users\\LENOVO\\Anaconda\\envs\\py36\\lib\\site-packages\\IPython\\core\\interactiveshell.py\", line 2044, in showtraceback\n",
      "    stb = value._render_traceback_()\n",
      "AttributeError: 'TypeError' object has no attribute '_render_traceback_'\n",
      "\n",
      "During handling of the above exception, another exception occurred:\n",
      "\n",
      "Traceback (most recent call last):\n",
      "  File \"C:\\Users\\LENOVO\\Anaconda\\envs\\py36\\lib\\site-packages\\IPython\\core\\interactiveshell.py\", line 2895, in _run_cell\n",
      "    return runner(coro)\n",
      "  File \"C:\\Users\\LENOVO\\Anaconda\\envs\\py36\\lib\\site-packages\\IPython\\core\\async_helpers.py\", line 68, in _pseudo_sync_runner\n",
      "    coro.send(None)\n",
      "  File \"C:\\Users\\LENOVO\\Anaconda\\envs\\py36\\lib\\site-packages\\IPython\\core\\interactiveshell.py\", line 3072, in run_cell_async\n",
      "    interactivity=interactivity, compiler=compiler, result=result)\n",
      "  File \"C:\\Users\\LENOVO\\Anaconda\\envs\\py36\\lib\\site-packages\\IPython\\core\\interactiveshell.py\", line 3282, in run_ast_nodes\n",
      "    self.showtraceback()\n",
      "  File \"C:\\Users\\LENOVO\\Anaconda\\envs\\py36\\lib\\site-packages\\IPython\\core\\interactiveshell.py\", line 2047, in showtraceback\n",
      "    value, tb, tb_offset=tb_offset)\n",
      "  File \"C:\\Users\\LENOVO\\Anaconda\\envs\\py36\\lib\\site-packages\\IPython\\core\\ultratb.py\", line 1436, in structured_traceback\n",
      "    self, etype, value, tb, tb_offset, number_of_lines_of_context)\n",
      "  File \"C:\\Users\\LENOVO\\Anaconda\\envs\\py36\\lib\\site-packages\\IPython\\core\\ultratb.py\", line 1336, in structured_traceback\n",
      "    self, etype, value, tb, tb_offset, number_of_lines_of_context\n",
      "  File \"C:\\Users\\LENOVO\\Anaconda\\envs\\py36\\lib\\site-packages\\IPython\\core\\ultratb.py\", line 1211, in structured_traceback\n",
      "    chained_exceptions_tb_offset)\n",
      "  File \"C:\\Users\\LENOVO\\Anaconda\\envs\\py36\\lib\\site-packages\\IPython\\core\\ultratb.py\", line 1150, in format_exception_as_a_whole\n",
      "    last_unique, recursion_repeat = find_recursion(orig_etype, evalue, records)\n",
      "  File \"C:\\Users\\LENOVO\\Anaconda\\envs\\py36\\lib\\site-packages\\IPython\\core\\ultratb.py\", line 451, in find_recursion\n",
      "    return len(records), 0\n",
      "TypeError: object of type 'NoneType' has no len()\n",
      "\n",
      "During handling of the above exception, another exception occurred:\n",
      "\n",
      "Traceback (most recent call last):\n",
      "  File \"C:\\Users\\LENOVO\\Anaconda\\envs\\py36\\lib\\site-packages\\IPython\\core\\interactiveshell.py\", line 2044, in showtraceback\n",
      "    stb = value._render_traceback_()\n",
      "AttributeError: 'TypeError' object has no attribute '_render_traceback_'\n",
      "\n",
      "During handling of the above exception, another exception occurred:\n",
      "\n",
      "Traceback (most recent call last):\n",
      "  File \"C:\\Users\\LENOVO\\Anaconda\\envs\\py36\\lib\\site-packages\\IPython\\core\\ultratb.py\", line 1169, in get_records\n",
      "    return _fixed_getinnerframes(etb, number_of_lines_of_context, tb_offset)\n",
      "  File \"C:\\Users\\LENOVO\\Anaconda\\envs\\py36\\lib\\site-packages\\IPython\\core\\ultratb.py\", line 316, in wrapped\n",
      "    return f(*args, **kwargs)\n",
      "  File \"C:\\Users\\LENOVO\\Anaconda\\envs\\py36\\lib\\site-packages\\IPython\\core\\ultratb.py\", line 350, in _fixed_getinnerframes\n",
      "    records = fix_frame_records_filenames(inspect.getinnerframes(etb, context))\n",
      "  File \"C:\\Users\\LENOVO\\Anaconda\\envs\\py36\\lib\\inspect.py\", line 1490, in getinnerframes\n",
      "    frameinfo = (tb.tb_frame,) + getframeinfo(tb, context)\n",
      "  File \"C:\\Users\\LENOVO\\Anaconda\\envs\\py36\\lib\\inspect.py\", line 1448, in getframeinfo\n",
      "    filename = getsourcefile(frame) or getfile(frame)\n",
      "  File \"C:\\Users\\LENOVO\\Anaconda\\envs\\py36\\lib\\inspect.py\", line 696, in getsourcefile\n",
      "    if getattr(getmodule(object, filename), '__loader__', None) is not None:\n",
      "  File \"C:\\Users\\LENOVO\\Anaconda\\envs\\py36\\lib\\inspect.py\", line 733, in getmodule\n",
      "    if ismodule(module) and hasattr(module, '__file__'):\n",
      "  File \"C:\\Users\\LENOVO\\Anaconda\\envs\\py36\\lib\\site-packages\\tensorflow\\__init__.py\", line 50, in __getattr__\n",
      "    module = self._load()\n",
      "  File \"C:\\Users\\LENOVO\\Anaconda\\envs\\py36\\lib\\site-packages\\tensorflow\\__init__.py\", line 44, in _load\n",
      "    module = _importlib.import_module(self.__name__)\n",
      "  File \"C:\\Users\\LENOVO\\Anaconda\\envs\\py36\\lib\\importlib\\__init__.py\", line 126, in import_module\n",
      "    return _bootstrap._gcd_import(name[level:], package, level)\n",
      "  File \"<frozen importlib._bootstrap>\", line 994, in _gcd_import\n",
      "  File \"<frozen importlib._bootstrap>\", line 971, in _find_and_load\n",
      "  File \"<frozen importlib._bootstrap>\", line 953, in _find_and_load_unlocked\n",
      "ModuleNotFoundError: No module named 'tensorflow_core.estimator'\n"
     ]
    }
   ],
   "source": [
    "mnist_train,mnist_test = mnist_dataset['train'].mnist_dataset['test']\n",
    "num_validation_samples = 0.1*mnist_info.splits['train'].num_examples\n",
    "num_validation_samples = tf.cast(num_validation_samples,tf.int64)\n",
    "\n",
    "num_test_samples = mnist_info.splits['test'].num_examples\n",
    "num_ttest_samples = tf.cast(num_test_samples,tf.int64)\n",
    "def scale(image,label):\n",
    "    imagev= tf.cast(image,tf.float32)\n",
    "    image/=255.\n",
    "    return image , label\n",
    "scaled_train_and_validation_data = mnist_train.map(scale)\n",
    "\n",
    "test_data = mnist_test.map(scale)"
   ]
  },
  {
   "cell_type": "code",
   "execution_count": null,
   "metadata": {},
   "outputs": [],
   "source": []
  }
 ],
 "metadata": {
  "kernelspec": {
   "display_name": "Python [conda env:py36]",
   "language": "python",
   "name": "conda-env-py36-py"
  },
  "language_info": {
   "codemirror_mode": {
    "name": "ipython",
    "version": 3
   },
   "file_extension": ".py",
   "mimetype": "text/x-python",
   "name": "python",
   "nbconvert_exporter": "python",
   "pygments_lexer": "ipython3",
   "version": "3.6.13"
  }
 },
 "nbformat": 4,
 "nbformat_minor": 2
}
